<?xml version="1.0" ?>
<sdf version='1.11' xmlns:xacro='http://ros.org/wiki/xacro'>
  <model name='scout_mini'>

    <link name="base_footprint"/>

    <joint name="base_joint" type="fixed">
      <parent>base_footprint</parent>
      <child>base_link</child>
      <pose>0.0 0.0 0.010 0 0 0</pose>
    </joint>

    <link name='base_link'>
      <inertial>
        <pose>0 0 0 1.5700000000000001 5.5511151231257827e-17 -1.5700000000000001</pose>
        <mass>60</mass>
        <inertia>
          <ixx>2.2886410000000001</ixx>
          <ixy>0</ixy>
          <ixz>0</ixz>
          <iyy>5.1039760000000003</iyy>
          <iyz>0</iyz>
          <izz>3.4314650000000002</izz>
        </inertia>
      </inertial>
      <collision name='base_link_collision'>
        <pose>0 0 0 1.5700000000000001 -5.5511151231257827e-17 1.5700000000000001</pose>
        <geometry>
          <mesh>
            <scale>1 1 1</scale>
            <uri>model://scout_mini_base_link2.dae</uri>
          </mesh>
        </geometry>
        <surface>
          <contact>
            <ode/>
          </contact>
          <friction>
            <ode>
              <mu>0.20000000000000001</mu>
              <mu2>0.20000000000000001</mu2>
            </ode>
          </friction>
        </surface>
      </collision>
      <visual name='base_link_visual'>
        <pose>0 0 0 1.5700000000000001 5.5511151231257827e-17 -1.5700000000000001</pose>
        <geometry>
          <mesh>
            <scale>1 1 1</scale>
            <uri>model://scout_mini_base_link2.dae</uri>
          </mesh>
        </geometry>
      </visual>
    </link>
    <joint name='front_left_wheel' type='revolute'>
      <pose relative_to='base_link'>0.2319755 0.20825150000000001 -0.100998 -1.5700000000000001 0 0</pose>
      <parent>base_link</parent>
      <child>front_left_wheel_link</child>
      <axis>
        <xyz>0 0 1</xyz>
        <limit>
          <lower>-inf</lower>
          <upper>inf</upper>
        </limit>
        <dynamics>
          <spring_reference>0</spring_reference>
          <spring_stiffness>0</spring_stiffness>
        </dynamics>
      </axis>
    </joint>
    <link name='front_left_wheel_link'>
      <pose relative_to='front_left_wheel'>0 0 0 0 0 0</pose>
      <inertial>
        <pose>0 0 0 0 0 0</pose>
        <mass>3</mass>
        <inertia>
          <ixx>0.71709999999999996</ixx>
          <ixy>0</ixy>
          <ixz>0</ixz>
          <iyy>0.71709999999999996</iyy>
          <iyz>0</iyz>
          <izz>0.1361</izz>
        </inertia>
      </inertial>
      <collision name='front_left_wheel_link_collision'>
        <pose>0 0 0 0 0 0</pose>
        <geometry>
          <mesh>
            <scale>1 1 1</scale>
            <uri>model://wheel.dae</uri>
          </mesh>
        </geometry>
        <surface>
          <contact>
            <ode/>
          </contact>
          <friction>
            <ode>
              <mu>0.20000000000000001</mu>
              <mu2>0.20000000000000001</mu2>
            </ode>
          </friction>
        </surface>
      </collision>
      <visual name='front_left_wheel_link_visual'>
        <pose>0 0 0 0 0 0</pose>
        <geometry>
          <mesh>
            <scale>1 1 1</scale>
            <uri>model://wheel.dae</uri>
          </mesh>
        </geometry>
      </visual>
    </link>
    <joint name='front_right_wheel' type='revolute'>
      <pose relative_to='base_link'>0.2319755 -0.20825150000000001 -0.099998000000000004 1.5700000000000001 0 0</pose>
      <parent>base_link</parent>
      <child>front_right_wheel_link</child>
      <axis>
        <xyz>0 0 -1</xyz>
        <limit>
          <lower>-inf</lower>
          <upper>inf</upper>
        </limit>
        <dynamics>
          <spring_reference>0</spring_reference>
          <spring_stiffness>0</spring_stiffness>
        </dynamics>
      </axis>
    </joint>
    <link name='front_right_wheel_link'>
      <pose relative_to='front_right_wheel'>0 0 0 0 0 0</pose>
      <inertial>
        <pose>0 0 0 0 0 0</pose>
        <mass>3</mass>
        <inertia>
          <ixx>0.71709999999999996</ixx>
          <ixy>0</ixy>
          <ixz>0</ixz>
          <iyy>0.71709999999999996</iyy>
          <iyz>0</iyz>
          <izz>0.1361</izz>
        </inertia>
      </inertial>
      <collision name='front_right_wheel_link_collision'>
        <pose>0 0 0 0 0 0</pose>
        <geometry>
          <mesh>
            <scale>1 1 1</scale>
            <uri>model://wheel.dae</uri>
          </mesh>
        </geometry>
        <surface>
          <contact>
            <ode/>
          </contact>
          <friction>
            <ode>
              <mu>0.20000000000000001</mu>
              <mu2>0.20000000000000001</mu2>
            </ode>
          </friction>
        </surface>
      </collision>
      <visual name='front_right_wheel_link_visual'>
        <pose>0 0 0 0 0 0</pose>
        <geometry>
          <mesh>
            <scale>1 1 1</scale>
            <uri>model://wheel.dae</uri>
          </mesh>
        </geometry>
      </visual>
    </link>
    <joint name='rear_left_wheel' type='revolute'>
      <pose relative_to='base_link'>-0.2319755 0.20825150000000001 -0.100998 -1.5700000000000001 0 0</pose>
      <parent>base_link</parent>
      <child>rear_left_wheel_link</child>
      <axis>
        <xyz>0 0 1</xyz>
        <limit>
          <lower>-inf</lower>
          <upper>inf</upper>
        </limit>
        <dynamics>
          <spring_reference>0</spring_reference>
          <spring_stiffness>0</spring_stiffness>
        </dynamics>
      </axis>
    </joint>
    <link name='rear_left_wheel_link'>
      <pose relative_to='rear_left_wheel'>0 0 0 0 0 0</pose>
      <inertial>
        <pose>0 0 0 0 0 0</pose>
        <mass>3</mass>
        <inertia>
          <ixx>0.71709999999999996</ixx>
          <ixy>0</ixy>
          <ixz>0</ixz>
          <iyy>0.71709999999999996</iyy>
          <iyz>0</iyz>
          <izz>0.1361</izz>
        </inertia>
      </inertial>
      <collision name='rear_left_wheel_link_collision'>
        <pose>0 0 0 0 0 0</pose>
        <geometry>
          <mesh>
            <scale>1 1 1</scale>
            <uri>model://wheel.dae</uri>
          </mesh>
        </geometry>
        <surface>
          <contact>
            <ode/>
          </contact>
          <friction>
            <ode>
              <mu>0.20000000000000001</mu>
              <mu2>0.20000000000000001</mu2>
            </ode>
          </friction>
        </surface>
      </collision>
      <visual name='rear_left_wheel_link_visual'>
        <pose>0 0 0 0 0 0</pose>
        <geometry>
          <mesh>
            <scale>1 1 1</scale>
            <uri>model://wheel.dae</uri>
          </mesh>
        </geometry>
      </visual>
    </link>
    <joint name='rear_right_wheel' type='revolute'>
      <pose relative_to='base_link'>-0.2319755 -0.20825150000000001 -0.099998000000000004 1.5700000000000001 0 0</pose>
      <parent>base_link</parent>
      <child>rear_right_wheel_link</child>
      <axis>
        <xyz>0 0 -1</xyz>
        <limit>
          <lower>-inf</lower>
          <upper>inf</upper>
        </limit>
        <dynamics>
          <spring_reference>0</spring_reference>
          <spring_stiffness>0</spring_stiffness>
        </dynamics>
      </axis>
    </joint>
    <link name='rear_right_wheel_link'>
      <pose relative_to='rear_right_wheel'>0 0 0 0 0 0</pose>
      <inertial>
        <pose>0 0 0 0 0 0</pose>
        <mass>3</mass>
        <inertia>
          <ixx>0.71709999999999996</ixx>
          <ixy>0</ixy>
          <ixz>0</ixz>
          <iyy>0.71709999999999996</iyy>
          <iyz>0</iyz>
          <izz>0.1361</izz>
        </inertia>
      </inertial>
      <collision name='rear_right_wheel_link_collision'>
        <pose>0 0 0 0 0 0</pose>
        <geometry>
          <mesh>
            <scale>1 1 1</scale>
            <uri>model://wheel.dae</uri>
          </mesh>
        </geometry>
        <surface>
          <contact>
            <ode/>
          </contact>
          <friction>
            <ode>
              <mu>0.20000000000000001</mu>
              <mu2>0.20000000000000001</mu2>
            </ode>
          </friction>
        </surface>
      </collision>
      <visual name='rear_right_wheel_link_visual'>
        <pose>0 0 0 0 0 0</pose>
        <geometry>
          <mesh>
            <scale>1 1 1</scale>
            <uri>model://wheel.dae</uri>
          </mesh>
        </geometry>
      </visual>
    </link>

    <joint name="tower_joint" type="fixed">
      <parent>base_link</parent>
      <child>tower_link</child>
      <pose relative_to="base_link">0.09 -0.04 -0.81 0 0 -1.5708</pose>
    </joint>

    <link name='tower_link'>
      <pose relative_to="tower_joint"/>
      <visual name="tower_link_visual">
        <pose>0 0 0 0 0 0</pose>
        <geometry>
          <mesh>
            <scale>1 1 1</scale>
            <uri>model://perifericos.dae</uri>
          </mesh>
        </geometry>
      </visual>
    </link>
    
    <frame name='inertial_joint' attached_to='base_link'>
      <pose>0 0 0 0 0 0</pose>
    </frame>
    <frame name='inertial_link' attached_to='inertial_joint'>
      <pose>0 0 0 0 0 0</pose>
    </frame>

    <joint name='imu_joint' type='fixed'>
      <parent>base_link</parent>
      <child>imu_link</child>
      <pose relative_to="base_link">0 0 0 0 0 0</pose>
    </joint>

    <link name='imu_link'>
      <pose relative_to="imu_joint"/>
      <visual name="imu_link_visual">
        <geometry>
          <box><size>
            0.1 0.1 0.1
          </size></box>
        </geometry>
      </visual>

      <collision name="imu_link_collision">
        <geometry>
          <box><size>
            0.1 0.1 0.1
          </size></box>
        </geometry>
      </collision>

      <sensor name="imu_sensor" type="imu">
        <always_on>true</always_on>
        <update_rate>100</update_rate>
        <visualize>true</visualize>
        <topic>imu</topic>
        <gz_frame_id>imu_link</gz_frame_id>
        <imu>
          <angular_velocity>
            <x>
              <noise type="gaussian">
                <mean>0.0</mean>
                <stddev>2e-4</stddev>
                <bias_mean>0.0000075</bias_mean>
                <bias_stddev>0.0000008</bias_stddev>
              </noise>
            </x>
            <y>
              <noise type="gaussian">
                <mean>0.0</mean>
                <stddev>2e-4</stddev>
                <bias_mean>0.0000075</bias_mean>
                <bias_stddev>0.0000008</bias_stddev>
              </noise>
            </y>
            <z>
              <noise type="gaussian">
                <mean>0.0</mean>
                <stddev>2e-4</stddev>
                <bias_mean>0.0000075</bias_mean>
                <bias_stddev>0.0000008</bias_stddev>
              </noise>
            </z>
          </angular_velocity>
          <linear_acceleration>
            <x>
              <noise type="gaussian">
                <mean>0.0</mean>
                <stddev>1.7e-2</stddev>
                <bias_mean>0.1</bias_mean>
                <bias_stddev>0.001</bias_stddev>
              </noise>
            </x>
            <y>
              <noise type="gaussian">
                <mean>0.0</mean>
                <stddev>1.7e-2</stddev>
                <bias_mean>0.1</bias_mean>
                <bias_stddev>0.001</bias_stddev>
              </noise>
            </y>
            <z>
              <noise type="gaussian">
                <mean>0.0</mean>
                <stddev>1.7e-2</stddev>
                <bias_mean>0.1</bias_mean>
                <bias_stddev>0.001</bias_stddev>
              </noise>
            </z>
          </linear_acceleration>
        </imu>
      </sensor>
    </link>

    <joint name="lidar_joint" type="fixed">
      <parent>base_link</parent>
      <child>lidar_link</child>
      <pose relative_to="base_link">0 0 0.3 0 0 0</pose>
    </joint>

    <link name='lidar_link'>
      <pose relative_to="lidar_joint"/>
      <!-- <visual name="lidar_link_visual">
        <geometry>
          <mesh>
            <scale>1 1 1</scale>
            <uri>model://perifericos.dae</uri>
          </mesh>
        </geometry>
      </visual>
      <collision name="lidar_link_collision">
        <geometry>
          <mesh>
            <scale>1 1 1</scale>
            <uri>model://perifericos.dae</uri>
          </mesh>
        </geometry>
      </collision> -->
      <sensor name="lidar" type="gpu_lidar">
        <always_on>true</always_on>
        <visualize>true</visualize>
        <update_rate>5</update_rate>
        <topic>scan</topic>
        <gz_frame_id>lidar_link</gz_frame_id>
        <lidar>
          <scan>
            <horizontal>
              <samples>90</samples>
              <resolution>1.000000</resolution>
              <min_angle>0.000000</min_angle>
              <max_angle>6.280000</max_angle>
            </horizontal>
            <vertical>
              <samples>90</samples>         
              <resolution>1</resolution>
              <min_angle>-0.261799</min_angle> 
              <max_angle>0.261799</max_angle>  
            </vertical>
          </scan>
          <range>
            <min>0.120000</min>
            <max>3.5</max>
            <resolution>0.015000</resolution>
          </range>
          <noise>
            <type>gaussian</type>
            <mean>0.0</mean>
            <stddev>0.01</stddev>
          </noise>
        </lidar>
      </sensor>
    </link>

    <joint name="camera_joint" type="fixed">
      <parent>base_link</parent>
      <child>camera_link</child>
      <pose relative_to="base_link">0.215 0 0.05 0 0 0</pose>
    </joint> 

    <link name='camera_link'>
      <pose relative_to="camera_joint"/>
      <!-- <visual name="camera_link_visual">
        <geometry>
          <box><size>
            0.015 0.130 0.0222
          </size></box>
        </geometry>
      </visual>
      <collision name="camera_link_collision">
        <geometry>
          <box><size>
            0.015 0.130 0.0222
          </size></box>
        </geometry>
      </collision> -->
      <sensor name="depth_camera" type="rgbd_camera">
        <always_on>true</always_on>
        <visualize>true</visualize>
        <update_rate>5.0</update_rate>
        <topic>depth_camera</topic>
        <gz_frame_id>camera_link</gz_frame_id>
        <camera>
          <horizontal_fov>1.047198</horizontal_fov>
          <image>
            <width>640</width>
            <height>480</height>
          </image>
          <clip>
            <near>1</near>
            <far>3</far>
          </clip>
        </camera>
        <baseline>0.2</baseline>
        <pointCloudCutoff>0.5</pointCloudCutoff>
        <pointCloudCutoffMax>3.0</pointCloudCutoffMax>
        <distortionK1>0</distortionK1>
        <distortionK2>0</distortionK2>
        <distortionK3>0</distortionK3>
        <distortionT1>0</distortionT1>
        <distortionT2>0</distortionT2>
        <CxPrime>0</CxPrime>
        <Cx>0</Cx>
        <Cy>0</Cy>
        <focalLength>0</focalLength>
        <hackBaseline>0</hackBaseline>
      </sensor>
    </link>
    <joint name='pan_joint' type='revolute'>
      <pose relative_to='base_link'>0 0 0 0 0 0</pose>
      <parent>base_link</parent>
      <child>pan_link</child>
      <axis>
        <xyz>0 0 1</xyz>
        <limit>
          <lower>-2.6000000000000001</lower>
          <upper>2.6000000000000001</upper>
          <effort>20</effort>
          <velocity>2</velocity>
        </limit>
        <dynamics>
          <damping>0.050000000000000003</damping>
          <friction>0.01</friction>
          <spring_reference>0</spring_reference>
          <spring_stiffness>0</spring_stiffness>
        </dynamics>
      </axis>
    </joint>
    <link name='pan_link'>
      <pose relative_to="base_link">0.22 0 0.045 0 0 0</pose>
      <inertial>
        <pose>0 0 0 0 0 0</pose>
        <mass>0.15</mass>
        <inertia>
          <ixx>0.0005</ixx>
          <iyy>0.0005</iyy>
          <izz>0.0005</izz>
          <ixy>0</ixy>
          <ixz>0</ixz>
          <iyz>0</iyz>
        </inertia>
      </inertial>
      <visual name='pan_visual'>
        <pose>0 0 0 0 0 0</pose>
        <geometry>
          <mesh>
            <scale>0.4 0.4 0.4</scale>
            <uri>model://pan.dae</uri>
          </mesh>
        </geometry>
      </visual>
    </link>
    <joint name='tilt_joint' type='revolute'>
      <pose relative_to='pan_link'>0 0 0 0 0 0</pose>
      <parent>pan_link</parent>
      <child>tilt_link</child>
      <axis>
        <xyz>0 1 0</xyz>
        <limit>
          <lower>-1.5707960000000001</lower>
          <upper>1.5707960000000001</upper>
          <effort>20</effort>
          <velocity>2</velocity>
        </limit>
        <dynamics>
          <damping>0.10000000000000001</damping>
          <friction>0.5</friction>
          <spring_reference>0</spring_reference>
          <spring_stiffness>0</spring_stiffness>
        </dynamics>
      </axis>
    </joint>
    <link name='tilt_link'>
      <pose relative_to="base_link">0.225 0 0.105 0 0 0</pose>
      <inertial>
        <pose>0 0 0 0 0 0</pose>
        <mass>0.15</mass>
        <inertia>
          <ixx>0.0005</ixx>
          <iyy>0.0005</iyy>
          <izz>0.0005</izz>
          <ixy>0</ixy>
          <ixz>0</ixz>
          <iyz>0</iyz>
        </inertia>
      </inertial>
      <visual name='tilt_visual'>
        <pose>0 0 0 0 0 0</pose>
        <geometry>
          <mesh>
            <scale>0.4 0.4 0.4</scale>
            <uri>model://tilt.dae</uri>
          </mesh>
        </geometry>
      </visual>
      <sensor name="camera" type="camera">
        <always_on>true</always_on>
        <visualize>true</visualize>
        <update_rate>5.0</update_rate>
        <topic>payload_camera/image</topic>
        <camera>
          <horizontal_fov>1.0471980000000001</horizontal_fov>
          <image>
            <width>640</width>
            <height>480</height>
          </image>
          <clip>
            <near>0.050000000000000003</near>
            <!-- <far>100</far> -->
          </clip>
          <noise type="gaussian">
            <mean>0.0</mean>
            <stddev>0.007</stddev>
          </noise>
        </camera>
      </sensor>
    </link>
    
    <plugin
    filename="gz-sim-joint-position-controller-system"
    name="gz::sim::systems::JointPositionController">
      <joint_name>pan_joint</joint_name>
      <topic>pan_camera_cmd</topic>
      <p_gain>1</p_gain>
      <i_gain>0.1</i_gain>
      <d_gain>0.1</d_gain>
      <i_max>1</i_max>
      <i_min>-1</i_min>
      <cmd_max>1000</cmd_max>
      <cmd_min>-1000</cmd_min>
    </plugin>

    <plugin
    filename="gz-sim-joint-position-controller-system"
    name="gz::sim::systems::JointPositionController">
      <joint_name>tilt_joint</joint_name>
      <topic>tilt_camera_cmd</topic>
      <p_gain>4</p_gain>
      <i_gain>0.1</i_gain>
      <d_gain>0.1</d_gain>
      <i_max>1</i_max>
      <i_min>-1</i_min>
      <cmd_max>1000</cmd_max>
      <cmd_min>-1000</cmd_min>
    </plugin>

    <plugin
        name="gz::sim::systems::PosePublisher"
        filename="gz-sim-pose-publisher-system">
        <publish_link_pose>true</publish_link_pose>
        <publish_model_pose>true</publish_model_pose>
        <tf> true </tf>
    </plugin>

    <plugin
      name="gz::sim::systems::OdometryPublisher"
      filename="gz-sim-odometry-publisher-system">
      <odom_frame>odom</odom_frame>
      <base_frame>base_link</base_frame>
      <topic>odom</topic>
    </plugin>

    <plugin name='gz::sim::systems::DiffDrive' filename='gz-sim-diff-drive-system'>
      <left_joint>front_left_wheel</left_joint>
      <right_joint>front_right_wheel</right_joint>
      <left_joint>rear_left_wheel</left_joint>
      <right_joint>rear_right_wheel</right_joint>
      <wheel_separation>0.451</wheel_separation>
      <wheel_radius>0.08</wheel_radius>
      <max_linear_acceleration>0.8</max_linear_acceleration>
      <topic>cmd_vel</topic>
      <odom_topic>odom</odom_topic>
      <frame_id>odom</frame_id>
      <child_frame_id>base_footprint</child_frame_id>
      <odom_publisher_frequency>30</odom_publisher_frequency>
    </plugin>

    <plugin
      filename="gz-sim-pose-publisher-system"
      name="gz::sim::systems::PosePublisher">
      <use_pose_vector_msg>true</use_pose_vector_msg>
      <publish_nested_model_pose>true</publish_nested_model_pose>
    </plugin>

    <plugin name='gz::sim::systems::JointStatePublisher' filename='gz-sim-joint-state-publisher-system'>
      <topic>joint_states</topic>
      <joint_name>front_left_wheel</joint_name>
      <joint_name>front_right_wheel</joint_name>
      <joint_name>rear_left_wheel</joint_name>
      <joint_name>rear_right_wheel</joint_name>
      <joint_name>pan_joint</joint_name>
      <joint_name>tilt_joint</joint_name>
    </plugin>
  </model>
</sdf>

